Workbook

Sheet Visão Geral
A1: PLANO DE ACOMPANHAMENTO — APP DO AMOR + MPV DE TESTE
A2: Atualizado em | B2: 16/09/2026 21:11
A3: Indicador | B3: Valor | C3: Leitura
A4: Total de tarefas | B4: =COUNTA('Plano Mestre'!A2:A140) -> 0 | C4: escopo completo
A5: Tarefas concluídas | B5: =COUNTIF('Plano Mestre'!I2:I140,"Concluído") -> 0 | C5: entregas finalizadas
A6: Em andamento | B6: =COUNTIF('Plano Mestre'!I2:I140,"Em andamento") -> 0 | C6: trabalho ativo
A7: Não iniciadas | B7: =COUNTIF('Plano Mestre'!I2:I140,"Não iniciado") -> 0 | C7: fila restante
A8: Progresso por status | B8: =AVERAGE('Plano Mestre'!M2:M140) -> 0 | C8: não mede prontidão do produto
A9: Horas estimadas | B9: =SUM('Plano Mestre'!J2:J140) -> 0 | C9: esforço total
A11: FASES | B11: Tarefas | C11: Concluídas
A12: Descoberta | B12: =COUNTIF('Plano Mestre'!B2:B140,"Descoberta") -> 0 | C12: =COUNTIFS('Plano Mestre'!B2:B140,"Descoberta",'Plano Mestre'!I2:I140,"Concluído") -> 0
A13: Planejamento | B13: =COUNTIF('Plano Mestre'!B2:B140,"Planejamento") -> 0 | C13: =COUNTIFS('Plano Mestre'!B2:B140,"Planejamento",'Plano Mestre'!I2:I140,"Concluído") -> 0
A14: Marca | B14: =COUNTIF('Plano Mestre'!B2:B140,"Marca") -> 0 | C14: =COUNTIFS('Plano Mestre'!B2:B140,"Marca",'Plano Mestre'!I2:I140,"Concluído") -> 0
A15: UX/UI | B15: =COUNTIF('Plano Mestre'!B2:B140,"UX/UI") -> 0 | C15: =COUNTIFS('Plano Mestre'!B2:B140,"UX/UI",'Plano Mestre'!I2:I140,"Concluído") -> 0
A16: Arquitetura | B16: =COUNTIF('Plano Mestre'!B2:B140,"Arquitetura") -> 0 | C16: =COUNTIFS('Plano Mestre'!B2:B140,"Arquitetura",'Plano Mestre'!I2:I140,"Concluído") -> 0
A17: Infraestrutura | B17: =COUNTIF('Plano Mestre'!B2:B140,"Infraestrutura") -> 0 | C17: =COUNTIFS('Plano Mestre'!B2:B140,"Infraestrutura",'Plano Mestre'!I2:I140,"Concluído") -> 0
A18: Backend | B18: =COUNTIF('Plano Mestre'!B2:B140,"Backend") -> 0 | C18: =COUNTIFS('Plano Mestre'!B2:B140,"Backend",'Plano Mestre'!I2:I140,"Concluído") -> 0
A19: Frontend | B19: =COUNTIF('Plano Mestre'!B2:B140,"Frontend") -> 0 | C19: =COUNTIFS('Plano Mestre'!B2:B140,"Frontend",'Plano Mestre'!I2:I140,"Concluído") -> 0
A20: Conteúdo | B20: =COUNTIF('Plano Mestre'!B2:B140,"Conteúdo") -> 0 | C20: =COUNTIFS('Plano Mestre'!B2:B140,"Conteúdo",'Plano Mestre'!I2:I140,"Concluído") -> 0
A21: Qualidade | B21: =COUNTIF('Plano Mestre'!B2:B140,"Qualidade") -> 0 | C21: =COUNTIFS('Plano Mestre'!B2:B140,"Qualidade",'Plano Mestre'!I2:I140,"Concluído") -> 0
A22: Jurídico | B22: =COUNTIF('Plano Mestre'!B2:B140,"Jurídico") -> 0 | C22: =COUNTIFS('Plano Mestre'!B2:B140,"Jurídico",'Plano Mestre'!I2:I140,"Concluído") -> 0
A23: Lançamento | B23: =COUNTIF('Plano Mestre'!B2:B140,"Lançamento") -> 0 | C23: =COUNTIFS('Plano Mestre'!B2:B140,"Lançamento",'Plano Mestre'!I2:I140,"Concluído") -> 0
A24: Pós-lançamento | B24: =COUNTIF('Plano Mestre'!B2:B140,"Pós-lançamento") -> 0 | C24: =COUNTIFS('Plano Mestre'!B2:B140,"Pós-lançamento",'Plano Mestre'!I2:I140,"Concluído") -> 0
A25: MPV de teste | B25: =COUNTIF('Plano Mestre'!B2:B140,"MPV de teste") -> 0 | C25: =COUNTIFS('Plano Mestre'!B2:B140,"MPV de teste",'Plano Mestre'!I2:I140,"Concluído") -> 0

Sheet Plano Mestre
A1: ID | B1: Fase | C1: Área | D1: Tarefa | E1: Entregável | F1: Prioridade | G1: Dependência | H1: Responsável | I1: Status | J1: Estimativa (h) | K1: Início planejado | L1: Fim planejado | M1: % concluído | N1: Observações
A2: 1 | B2: Descoberta | C2: Produto | D2: Definir visão e proposta de valor | E2: Documento de visão | F2: Crítica | H2: Product Owner | I2: Concluído | J2: 4 | M2: 1 | N2: Visão revisada com foco em conexão descoberta intimidade diversão e fortalecimento do relacionamento em docs/VISAO-E-PROPOSTA-DE-VALOR.md
A3: 2 | B3: Descoberta | C3: Produto | D3: Definir público-alvo e personas | E3: Personas validadas | F3: Alta | G3: 1 | H3: Product Owner | I3: Em andamento | J3: 8 | M3: 0.5 | N3: Público e personas provisórias definidos em docs/PUBLICO-ALVO-E-PERSONAS.md, validação depende das entrevistas da tarefa 3
A4: 3 | B4: Descoberta | C4: Pesquisa | D4: Entrevistar casais do público-alvo | E4: Relatório de entrevistas | F4: Alta | G4: 2 | H4: Pesquisa e Conteúdo | I4: Em andamento | J4: 20 | M4: 0.5 | N4: Protocolo e ficha disponíveis em Markdown e Word na pasta docs — formulário nomeado como Jogo para Casais — Pesquisa de Experiência, texto introdutório informal e imagem de fundo sem marca disponíveis — pendentes montagem final do Forms, recrutamento, campo e síntese
A5: 4 | B5: Descoberta | C5: Pesquisa | D5: Mapear dores necessidades e hábitos | E5: Mapa de oportunidades | F5: Alta | G5: 3 | H5: Pesquisa e Conteúdo | I5: Em andamento | J5: 8 | M5: 0.5 | N5: Pesquisa secundária consolidada em docs/PESQUISA-CASAIS-BRASILEIROS.md - síntese das entrevistas e validação das oportunidades dependem da tarefa 3
A6: 5 | B6: Descoberta | C6: Mercado | D6: Analisar concorrentes diretos e indiretos | E6: Análise competitiva | F6: Média | G6: 1 | H6: Product Owner | I6: Concluído | J6: 8 | M6: 1 | N6: Mapeamento consolidado em docs/ANALISE-CONCORRENTES.md com benchmark incluindo Lovify posicionamento e oportunidades
A7: 6 | B7: Descoberta | C7: Negócio | D7: Definir modelo de negócio e monetização | E7: Modelo de receita | F7: Alta | G7: 4,5 | H7: Product Owner | I7: Concluído | J7: 8 | M7: 1 | N7: Freemium B2C e assinatura por casal definidos em docs/MODELO-DE-NEGOCIO-E-MONETIZACAO.md com preços unit economics e experimentos
A8: 7 | B8: Descoberta | C8: Produto | D8: Definir métricas de sucesso e North Star | E8: Árvore de métricas | F8: Alta | G8: 1 | H8: Product Owner | I8: Concluído | J8: 5 | M8: 1 | N8: North Star árvore de métricas metas e governança documentadas em docs/METRICAS-DE-SUCESSO.md
A9: 8 | B9: Planejamento | C9: Produto | D9: Consolidar PRD do produto | E9: PRD aprovado | F9: Crítica | G9: 2,4,6,7 | H9: Product Owner | I9: Em andamento | J9: 16 | M9: 0.5 | N9: PRD v0.9 consolidado em Markdown e Word, pendente validação das personas priorização final e aprovação
A10: 9 | B10: Planejamento | C10: Produto | D10: Priorizar funcionalidades pelo método MoSCoW | E10: Escopo priorizado | F10: Crítica | G10: 8 | H10: Product Owner | I10: Concluído | J10: 6 | M10: 1 | N10: Priorização da Release 1.0 consolidada em docs/PRIORIZACAO-MOSCOW.md e Word com Must Should Could Won't critérios e cortes
A11: 10 | B11: Planejamento | C11: Produto | D11: Definir escopo do MVP | E11: Backlog do MVP | F11: Crítica | G11: 9 | H11: Product Owner | I11: Concluído | J11: 6 | M11: 1 | N11: MVP piloto PWA de 6 semanas com 40 a 60 casais, três mecânicas e backlog de 38 itens consolidado em docs/ESCOPO-MVP.md e Word
A12: 11 | B12: Planejamento | C12: Gestão | D12: Definir cronograma marcos e cadência | E12: Roadmap de execução | F12: Alta | G12: 10 | H12: Product Owner | I12: Concluído | J12: 6 | K12: 07/09/2026 | L12: 05/03/2027 | M12: 1 | N12: Linha de base em docs/CRONOGRAMA-MARCOS-E-CADENCIA.md e Word - revisão identificou datas por tarefa e capacidade nominal pendentes de replanejamento com a baseline 112 - datas dos marcos permanecem premissas
A13: 12 | B13: Planejamento | C13: Gestão | D13: Definir responsáveis e matriz RACI | E13: Matriz RACI | F13: Média | G13: 11 | H13: Product Owner — Tatyele Lopes | I13: Concluído | J13: 4 | M13: 1 | N13: Estrutura de papéis e RACI documentadas - papéis padrão aplicados às tarefas atuais pelo gerador - nomes técnicos e capacidade ainda a confirmar - documento e Word têm recorte histórico das 107 tarefas iniciais
A14: 13 | B14: Planejamento | C14: Gestão | D14: Configurar gestão de backlog e cerimônias | E14: Quadro operacional | F14: Alta | G14: 11,12 | H14: Product Owner — Tatyele Lopes | I14: Concluído | J14: 4 | M14: 1 | N14: Kanban com ciclos quinzenais fluxo WIP DoR DoD RICE cerimônias e métricas configurados em docs/GESTAO-DE-BACKLOG-E-CERIMONIAS.md e na aba Governança Backlog
A15: 14 | B15: Marca | C15: Branding | D15: Validar nome Conectadois e alternativas | E15: Decisão de naming | F15: Alta | G15: 1 | H15: Product Designer | I15: Não iniciado | J15: 8 | M15: 0
A16: 15 | B16: Marca | C16: Jurídico | D16: Pesquisar disponibilidade no INPI | E16: Parecer preliminar | F16: Alta | G16: 14 | H16: Privacidade/Jurídico | I16: Não iniciado | J16: 4 | M16: 0
A17: 16 | B17: Marca | C17: Branding | D17: Registrar domínio e perfis sociais | E17: Ativos digitais reservados | F17: Alta | G17: 14 | H17: Product Designer | I17: Não iniciado | J17: 3 | M17: 0
A18: 17 | B18: Marca | C18: Branding | D18: Definir posicionamento tom de voz e slogan | E18: Guia verbal | F18: Média | G18: 14 | H18: Product Designer | I18: Concluído | J18: 8 | M18: 1 | N18: Posicionamento plataforma de mensagens tom de voz vocabulário aplicações e sistema de slogans consolidados em docs/POSICIONAMENTO-TOM-DE-VOZ-E-SLOGAN.md e Word — validar com casais e revisar se o naming mudar
A19: 18 | B19: Marca | C19: Design | D19: Consolidar logotipo paleta e tipografia | E19: Identidade visual | F19: Alta | G19: 14,17 | H19: Product Designer | I19: Concluído | J19: 16 | M19: 1 | N19: Identidade revisada conforme decisão da fundadora: símbolo 3D original da pasta Identidade visual restaurado no app e wordmark conectadois com dois em dourado — guia Word e preview horizontal atualizados
A20: 19 | B20: UX/UI | C20: Pesquisa | D20: Mapear jornada completa do casal | E20: Mapa de jornada e fluxograma visual | F20: Alta | G20: 8 | H20: Pesquisa e Conteúdo | I20: Concluído | J20: 12 | M20: 1 | N20: Jornada bilateral em 15 etapas consolidada em docs/JORNADA-COMPLETA-DO-CASAL.md e Word — fluxograma detalhado em docs/FLUXOGRAMA-JORNADA-COMPLETA-DO-CASAL.md e imagem vetorial pronta para compartilhamento em docs/FLUXOGRAMA-JORNADA-COMPLETA-DO-CASAL.svg — inclui decisões recuperações regras transversais e marcos mensuráveis — hipóteses pendentes de validação nas entrevistas
A21: 20 | B21: UX/UI | C21: Arquitetura | D21: Criar arquitetura de informação | E21: Mapa de navegação | F21: Alta | G21: 19 | H21: Product Designer | I21: Concluído | J21: 12 | M21: 1 | N21: Arquitetura mobile-first documentada em docs/ARQUITETURA-DE-INFORMACAO.md com mapa geral quatro áreas principais inventário de 29 telas objetos de informação regras de acesso rotas conceituais estados escopo por versão critérios de aceite e plano de validação
A22: 21 | B22: UX/UI | C22: UX | D22: Desenhar fluxo de onboarding | E22: Fluxo validado | F22: Crítica | G22: 20 | H22: Product Designer | I22: Em andamento | J22: 6 | M22: 0.5 | N22: Fluxo funcional completo documentado em docs/FLUXO-DE-ONBOARDING.md e diagrama compartilhável em docs/FLUXO-DE-ONBOARDING.svg — cobre descoberta direta convite recebido consentimento exceções acessibilidade analytics e critérios de aceite — pendentes protótipo navegável e validação com usuários nas tarefas 29 e 30
A23: 22 | B23: UX/UI | C23: UX | D23: Desenhar cadastro login e recuperação | E23: Fluxo validado | F23: Crítica | G23: 20 | H23: Product Designer | I23: Em andamento | J23: 8 | M23: 0.5 | N23: Fluxo funcional documentado em docs/FLUXO-DE-CADASTRO-LOGIN-E-RECUPERACAO.md e diagrama em docs/FLUXO-DE-CADASTRO-LOGIN-E-RECUPERACAO.svg — cobre conta individual contexto de convite validações verificação de e-mail recuperação de senha sessões segurança acessibilidade analytics e lacunas da implementação — pendentes protótipo e validação nas tarefas 29 e 30
A24: 23 | B24: UX/UI | C24: UX | D24: Desenhar pareamento e convite do casal | E24: Fluxo validado | F24: Crítica | G24: 20 | H24: Product Designer | I24: Em andamento | J24: 8 | M24: 0.5
A25: 24 | B25: UX/UI | C25: UX | D25: Desenhar home e rotina diária | E25: Fluxo validado | F25: Alta | G25: 20 | H25: Product Designer | I25: Em andamento | J25: 8 | M25: 0.5 | N25: Desenho em docs/HOME-E-ROTINA-DIARIA.md e protótipo navegável em docs/prototipo-home-rotina.html - 13 estados da home e rotina com perguntas desafios e modo misto - pendentes revisão visual e validação com casais na tarefa 30
A26: 25 | B26: UX/UI | C26: UX | D26: Desenhar perguntas e revelação mútua | E26: Fluxo validado | F26: Alta | G26: 20 | H26: Product Designer | I26: Em andamento | J26: 10 | M26: 0.5 | N26: Desenho em docs/PERGUNTAS-E-REVELACAO-MUTUA.md e protótipo docs/prototipo-perguntas-revelacao.html - discursiva múltipla escolha desafios espera correção pulo retomada e revelação bilateral - verificação de estados automatizada - validação visual e com casais pendentes na tarefa 30
A27: 26 | B27: UX/UI | C27: UX | D27: Desenhar testes e resultados | E27: Fluxo validado | F27: Alta | G27: 20 | H27: Product Designer | I27: Em andamento | J27: 10 | M27: 0.5 | N27: Desenho em docs/TESTES-E-RESULTADOS.md e protótipo docs/prototipo-testes-resultados.html - formas de afeto e temperamentos experimentais com pausa revisão resultado parcial empate compartilhamento opcional e revogação - verificação de estados em scripts/validate-tests-prototype.mjs - revisão visual editorial especializada e validação com casais pendentes
A28: 27 | B28: UX/UI | C28: Design | D28: Criar wireframes mobile-first | E28: Wireframes completos | F28: Alta | G28: 21-26 | H28: Product Designer | I28: Em andamento | J28: 20 | M28: 0.5 | N28: Home rotina diária perguntas com revelação e testes com resultados desenhados em protótipos HTML responsivos na pasta docs - demais telas e validação visual completa pendentes
A29: 28 | B29: UX/UI | C29: Design | D29: Criar design system e tokens | E29: Biblioteca visual | F29: Alta | G29: 18,27 | H29: Product Designer | I29: Em andamento | J29: 20 | M29: 0.5 | N29: Tokens em src/assets/brand/brand-tokens.css e guia docs/IDENTIDADE-VISUAL.md existentes - biblioteca de componentes estados acessibilidade e validação visual pendentes
A30: 29 | B30: UX/UI | C30: Design | D30: Produzir protótipo de alta fidelidade | E30: Protótipo navegável | F30: Alta | G30: 27,28 | H30: Product Designer | I30: Em andamento | J30: 30 | M30: 0.5 | N30: Protótipos locais da home perguntas e revelação mútua e testes com resultados em docs - inclui perspectivas simuladas rede pausa revisão e compartilhamento opcional de resumo - integração das demais jornadas revisão visual e testes com casais pendentes
A31: 30 | B31: UX/UI | C31: Pesquisa | D31: Executar teste de usabilidade | E31: Relatório de usabilidade | F31: Alta | G31: 29 | H31: Pesquisa e Conteúdo | I31: Em andamento | J31: 16 | M31: 0.5 | N31: Rodada 0 especializada executada em 05/09/2026 com sete jornadas bilaterais e doze estados responsivos - relatório em docs/TESTE-DE-USABILIDADE-2026-09-05.md - nove achados registrados - validação moderada com casais e métricas humanas ainda pendentes
A32: 31 | B32: UX/UI | C32: Design | D32: Aplicar melhorias do teste | E32: Protótipo aprovado | F32: Alta | G32: 30 | H32: Product Designer | I32: Não iniciado | J32: 12 | M32: 0 | N32: Correções dos achados UT-01 a UT-09 da rodada 0 pendentes - priorizar entrada em login feedback de falhas integridade do progresso retomada dos testes e alvos de toque antes da rodada com participantes
A33: 32 | B33: Arquitetura | C33: Engenharia | D33: Definir arquitetura frontend e backend | E33: Documento de arquitetura | F33: Crítica | G33: 10 | H33: Liderança Técnica | I33: Concluído | J33: 8 | M33: 1
A34: 33 | B34: Arquitetura | C34: Engenharia | D34: Definir padrão de pastas e dependências | E34: Convenções documentadas | F34: Alta | G34: 32 | H34: Liderança Técnica | I34: Concluído | J34: 5 | M34: 1
A35: 34 | B35: Arquitetura | C35: Dados | D35: Modelar usuários casais sessões respostas e progresso | E35: Modelo de dados | F35: Crítica | G35: 32 | H35: Engenharia Backend | I35: Concluído | J35: 12 | M35: 1 | N35: Modelo lógico em docs/MODELO-DE-DADOS.md e docs/modelo-de-dados.dbml com 10 entidades e 12 relacionamentos - autenticação partidas respostas desafios e progresso - regras de integridade privacidade e migração documentadas
A36: 35 | B36: Arquitetura | C36: API | D36: Definir contrato e versionamento da API | E36: Especificação OpenAPI | F36: Alta | G36: 34,112 | H36: Liderança Técnica | I36: Em andamento | J36: 12 | M36: 0.5 | N36: Contrato-base v1 em docs/openapi-v1.json com 21 caminhos 24 operações política de versões erros idempotência concorrência privacidade e migração documentados em docs/CONTRATO-E-VERSIONAMENTO-DA-API.md - validador em scripts/validate-openapi.mjs - estabilização 1.0 depende da decisão 112 threat model 36 LGPD 37 implementação e testes de conformidade
A37: 36 | B37: Arquitetura | C37: Segurança | D37: Realizar modelagem de ameaças | E37: Threat model | F37: Crítica | G37: 34,35 | H37: Liderança Técnica | I37: Concluído | J37: 12 | M37: 1 | N37: Baseline STRIDE e OWASP em docs/MODELAGEM-DE-AMEACAS.md com diagrama ativos fronteiras 23 ameaças 30 controles 21 testes gates de piloto e riscos residuais - 13 ameaças críticas 9 altas e 1 média - estado atual não apto para piloto externo - revalidar após tarefas 112-114 PostgreSQL provedores e antes da release candidate
A38: 37 | B38: Arquitetura | C38: Privacidade | D38: Mapear dados pessoais e base legal LGPD | E38: Inventário de dados | F38: Crítica | G38: 34 | H38: Privacidade/Jurídico | I38: Concluído | J38: 12 | K38: 05/09/2026 | L38: 05/09/2026 | M38: 1 | N38: Inventário v1 em docs/INVENTARIO-DE-DADOS-E-BASES-LEGAIS-LGPD.md - 17 grupos e 20 operações com finalidade necessidade bases dos artigos 7 e 11 acesso compartilhamento retenção direitos incidentes e gates - enquadramento sujeito a aprovação jurídica
A39: 38 | B39: Infraestrutura | C39: DevOps | D39: Definir ambientes local homologação produção | E39: Estratégia de ambientes | F39: Alta | G39: 32 | H39: DevOps/Plataforma | I39: Concluído | J39: 6 | M39: 1 | N39: Estratégia em docs/AMBIENTES.md com matriz local staging production isolamento configuração atual e futura promoção recuperação e gates - modelo .env.local.example e regras Git - definição concluída em 08/09/2026 sem provisionamento ou deploy remoto
A40: 39 | B40: Infraestrutura | C40: DevOps | D40: Configurar lint formatação e hooks | E40: Qualidade automatizada | F40: Alta | G40: 33 | H40: DevOps/Plataforma | I40: Concluído | J40: 6 | K40: 08/09/2026 | L40: 08/09/2026 | M40: 1 | N40: ESLint flat configurado para JavaScript TypeScript e React, Prettier e EditorConfig aplicados, hook pre-commit com Husky e lint-staged ativo e comandos de qualidade documentados no README
...

Sheet Marcos
A1: ID | B1: Marco | C1: Tarefas até | D1: Status | E1: Critério de aceite | F1: Data planejada | G1: Data real
A2: MPV1 | B2: Escopo e fluxo do teste aprovados | C2: 126 | D2: Concluído | E2: Dois jogos um aparelho critérios de decisão e fluxo documentados | F2: 12/09/2026
A3: MPV2 | B3: Dois jogos jogáveis | C3: 131 | D3: Concluído | E3: Jornadas completas com lote mínimo e feedback no produto | F3: 19/09/2026
A4: MPV3 | B4: Demonstração do teste pronta | C4: 135 | D4: Em andamento | E4: Link controlado disponível e QA em curso com aceite físico restrito ao Chrome | F4: 22/09/2026
A5: MPV4 | B5: Aprendizados incorporados | C5: 137 | D5: Não iniciado | E5: Sinais de cinco casais registrados como insumo para revisão futura do plano completo | F5: 28/09/2026
A6: MC1 | B6: Baseline aprovada | C6: 13 | D6: Em andamento | E6: PRD escopo MoSCoW papéis e pesquisa aprovados | F6: 18/09/2026
A7: MC2 | B7: Personas e oportunidades validadas | C7: 4 | D7: Em andamento | E7: 24 entrevistas analisadas e personas revisadas | F7: 02/10/2026
A8: MC3 | B8: Mecânicas e padrão editorial aprovados | C8: 31 | D8: Não iniciado | E8: Três protótipos testados e primeiro lote revisado | F8: 16/10/2026
A9: MC4 | B9: Fundação técnica pronta | C9: 123 | D9: Em andamento | E9: PostgreSQL CI segredos observabilidade recuperação 118 e homologação operacional 123 conforme estratégia 38 | F9: 23/10/2026
A10: MC5 | B10: MVP feature-complete | C10: 75 | D10: Em andamento | E10: Jornada bilateral validada incluindo 111 e 116 e métricas 106-107 — 113-114 conforme decisão 112 | F10: 20/11/2026
A11: MC6 | B11: Conteúdo do piloto aprovado | C11: 77 | D11: Não iniciado | E11: 60 atividades aprovadas com origem nível teste e revisão — tarefas 77 108 110 e 115 | F11: 27/11/2026
A12: MC7 | B12: Release candidate | C12: 96 | D12: Não iniciado | E12: QA segurança acessibilidade privacidade UAT e restauração 118 sem bloqueador — PWA 119 validada | F12: 18/12/2026
A13: MC8 | B13: Go/no-go do piloto | C13: 98 | D13: Não iniciado | E13: Coorte suporte métricas e release confirmados | F13: 08/01/2027
... A15: MC10 | B15: Decisão do MVP comercial | C15: 103 | D15: Não iniciado | E15: Relatório do piloto e recomendação aprovados | F15: 05/03/2027

Sheet Riscos
A1: ID | B1: Risco | C1: Categoria | D1: Probabilidade | E1: Impacto | F1: Mitigação | G1: Responsável | H1: Status
A2: R01 | B2: Privacidade de respostas íntimas | C2: Segurança | D2: Alta | E2: Crítico | F2: Criptografia autorização por casal e testes de isolamento | H2: Aberto
A3: R02 | B3: Baixa adesão do parceiro | C3: Produto | D3: Alta | E3: Alto | F3: Simplificar convite lembretes e medir conversão do pareamento | H3: Aberto
A4: R03 | B4: Conteúdo percebido como diagnóstico | C4: Conteúdo | D4: Média | E4: Alto | F4: Revisão por especialista e avisos claros de caráter educativo | H4: Aberto
A5: R04 | B5: Vazamento de credenciais ou sessões | C5: Segurança | D5: Média | E5: Crítico | F5: Hash forte expiração rotação e gestão de segredos | H5: Aberto
A6: R05 | B6: Atraso por escopo excessivo | C6: Gestão | D6: Alta | E6: Alto | F6: Proteger MVP controlar mudanças e revisar prioridades semanalmente | H6: Aberto
A7: R06 | B7: Dependência do armazenamento JSON | C7: Tecnologia | D7: Alta | E7: Alto | F7: Feedback remoto já usa PostgreSQL temporário - migrar os demais dados e provisionar banco definitivo antes da publicação ampla | H7: Aberto
A8: R07 | B8: Não conformidade com LGPD | C8: Jurídico | D8: Média | E8: Crítico | F8: Inventário v1 concluído — resolver DEC-01 a DEC-11 implementar consentimentos e direitos aprovar RIPD LIAs operadores e revisão jurídica | G8: Privacidade/Jurídico | H8: Aberto
A9: R08 | B9: Problemas de desempenho em mobile | C9: Tecnologia | D9: Média | E9: Médio | F9: Orçamento de performance imagens otimizadas e testes em aparelhos reais | H9: Aberto
A10: R09 | B10: Capacidade da equipe abaixo da premissa | C10: Gestão | D10: Alta | E10: Alto | F10: Confirmar responsáveis e horas recalcular datas ou reduzir amplitude antes do ciclo | H10: Aberto
A11: R10 | B11: Recesso e recrutamento atrasam o piloto | C11: Gestão | D11: Média | E11: Alto | F11: Antecipar UAT congelar escopo em dezembro e manter recrutamento contínuo | H11: Aberto
A12: R11 | B12: Autorização quebrada expõe dados entre casais | C12: Segurança | D12: Alta | E12: Crítico | F12: Autorização por sujeito ação e recurso DTOs mínimos e testes negativos ST-01 a ST-05 | G12: Liderança Técnica | H12: Aberto
A13: R12 | B13: Convite curto permite sequestro da segunda vaga | C13: Segurança | D13: Alta | E13: Crítico | F13: Pelo menos 128 bits hash expiração uso único rate limit e testes ST-06 a ST-08 | G13: Liderança Técnica | H13: Aberto
A14: R13 | B14: Eventos do cliente adulteram métricas do piloto | C14: Dados | D14: Alta | E14: Alto | F14: Derivar métricas críticas no servidor rejeitar eventos financeiros e testar replay | G14: Engenharia Backend | H14: Aberto
A15: R14 | B15: Cache ou notificação expõe conteúdo íntimo | C15: Privacidade | D15: Média | E15: Crítico | F15: No-store service worker sem S3 ou S4 notificações discretas e teste em aparelho compartilhado | G15: Privacidade/Jurídico | H15: Aberto
A16: MR01 | B16: Escopo do MPV crescer antes da validação | C16: MPV | D16: Alta | E16: Alto | F16: Bloquear novas áreas no teste e exigir a retirada de um item para qualquer inclusão | G16: Product Owner — Tatyele Lopes | H16: Aberto
A17: MR02 | B17: Regras dos jogos não serem entendidas sem ajuda | C17: MPV | D17: Média | E17: Alto | F17: Instrução em uma tela exemplo curto e critério de conclusão sem mediação | G17: Product Designer | H17: Aberto
A18: MR03 | B18: Perguntas do teste causarem desconforto | C18: MPV | D18: Baixa | E18: Alto | F18: Usar apenas cartas leves permitir pular e não armazenar respostas | G18: Conteúdo | H18: Aberto
A19: MR04 | B19: Conteúdo influenciar mais que o formato | C19: MPV | D19: Média | E19: Médio | F19: Equilibrar duração tema e quantidade de cartas entre os dois jogos | G19: Product Owner — Tatyele Lopes | H19: Aberto
A20: MR05 | B20: Falha no celular impedir a sessão de teste | C20: MPV | D20: Média | E20: Alto | F20: Validar o caminho crítico nos navegadores alvo e manter reinício simples | G20: Engenharia Frontend | H20: Aberto
A21: MR06 | B21: Sugestão aberta conter nomes contatos ou detalhes pessoais | C21: Privacidade | D21: Média | E21: Alto | F21: Limitar a 500 caracteres orientar a não inserir dados pessoais restringir a exportação e excluir a base gratuita em até 30 dias | G21: Privacidade/Jurídico | H21: Aberto

Sheet Governança Backlog
A1: GESTÃO DE BACKLOG E CERIMÔNIAS
A2: Modelo | B2: Kanban com compromisso quinzenal
A3: Dono da prioridade | B3: Product Owner — Tatyele Lopes
A4: Fonte operacional | B4: Plano Mestre; ferramenta externa deve referenciar o mesmo ID
A6: FLUXO | B6: REGRA DE SAÍDA | C6: WIP | D6: EQUIVALÊNCIA NO PLANO | E6: RESPONSÁVEL
A7: Funil | B7: Triagem realizada | C7: Sem limite | D7: Não iniciado | E7: PO
A8: Análise | B8: Descartar pesquisar ou detalhar | C8: 5 | D8: Não iniciado | E8: PO/TL
A9: Refinamento | B9: Definition of Ready atendida | C9: 8 | D9: Não iniciado | E9: PO/TL
A10: Pronto | B10: Selecionado no planejamento | C10: 10 | D10: Não iniciado | E10: PO
A11: Em andamento | B11: Incremento pronto para revisão | C11: 5 no time; 1 por pessoa | D11: Em andamento | E11: Dono do item
A12: Em revisão | B12: Parecer e ajustes concluídos | C12: 4 | D12: Em andamento | E12: Revisor aplicável
A13: Em validação | B13: Aceite registrado | C13: 4 | D13: Em andamento | E13: QA/PO
A14: Bloqueado | B14: Impedimento removido | C14: Exige ação | D14: Em andamento | E14: Dono + PO/TL
A15: Concluído | B15: Definition of Done atendida | C15: Sem limite | D15: Concluído | E15: PO/TL
A16: Cancelado | B16: Motivo registrado | C16: Sem limite | D16: Cancelado | E16: PO
A18: CERIMÔNIA | B18: CADÊNCIA | C18: DURAÇÃO | D18: FACILITADOR | E18: SAÍDA
... A28: Go/no-go | B28: Por marco | C28: Conforme pauta | D28: PO | E28: Decisão e condições
A30: DEFINITION OF READY | B30: CRITÉRIO
A31: Ready 1 | B31: Problema, resultado e responsável claros
A32: Ready 2 | B32: Aceite testável, dependências e riscos conhecidos
A33: Ready 3 | B33: Privacidade, segurança, acessibilidade e analytics avaliados
A34: Ready 4 | B34: Cabe no ciclo; PO confirma valor e TL viabilidade
A36: DEFINITION OF DONE | B36: CRITÉRIO
A37: Done 1 | B37: Aceite demonstrado e aprovado
A38: Done 2 | B38: Revisões e testes aplicáveis aprovados
A39: Done 3 | B39: Analytics, documentação e plano atualizados
A40: Done 4 | B40: Sem bloqueador; PO aceita e TL autoriza liberação
A42: CLASSE | B42: USO | C42: TRIAGEM
A43: P0 — Expedite | B43: Segurança, privacidade, integridade ou produção indisponível | C43: Imediata
A44: P1 — Crítico | B44: Jornada principal ou marco bloqueado | C44: Mesmo dia útil
A45: P2 — Padrão | B45: Planejado ou defeito com contorno | C45: Próxima triagem/ciclo
A46: P3 — Oportunidade | B46: Melhoria sem urgência ou evidência | C46: Revisão mensal
A48: MÉTRICA | B48: META INICIAL
A49: Objetivo do ciclo cumprido | B49: ≥ 80% dos ciclos
A50: Itens planejados que entram Ready | B50: 100%
A51: Trabalho não planejado | B51: ≤ 15% da capacidade
A52: Bloqueios acima de 2 dias | B52: 0 críticos; ≤ 2 totais
A53: Retrabalho/reabertura | B53: ≤ 10%
A54: Itens simultâneos por pessoa | B54: ≤ 1
A55: Defeitos P0/P1 ao fim do ciclo | B55: 0
